Workbook

Sheet 📋 คำแนะนำ
B1: 📊 เครื่องมือวิเคราะห์ข้อมูลวิจัย | Four-tier + POE | คลื่นกล ม.5
B2: รูปแบบการสอน: 5E + POE + สื่อดิจิทัล | วิจัยในชั้นเรียน | ระดับชั้น ม.5
B4: Sheet | C4: ชื่อ Sheet | D4: ใช้สำหรับ | E4: ป้อนข้อมูลที่
B5: 1 | C5: 📋 คำแนะนำ | D5: อ่านก่อนใช้งาน — โครงสร้างและวิธีใช้ทั้งหมด | E5: —
B6: 2 | C6: 📥 ข้อมูลนักเรียน | D6: กรอกรายชื่อนักเรียนและข้อมูลพื้นฐาน 1 ครั้ง | E6: คอลัมน์ B–G
B7: 3 | C7: 🔬 POE บันทึก | D7: กรอกคะแนน POE แต่ละแผนการสอน (10 แผน) | E7: คอลัมน์ D–M
B8: 4 | C8: 📝 Four-tier กรอก | D8: กรอกคำตอบ Tier 1–4 ของนักเรียนแต่ละคน | E8: คอลัมน์ D–Q
B9: 5 | C9: 🤖 Four-tier วิเคราะห์ | D9: Auto-classify: Sound/Misconception/Guess/NoK | E9: ไม่ต้องกรอก (Auto)
B10: 6 | C10: 📊 สรุป Misconception | D10: ตาราง M1–M5 ก่อน/หลังเรียน + เปอร์เซ็นต์ | E10: ไม่ต้องกรอก (Auto)
B11: 7 | C11: 📈 Dashboard | D11: กราฟสรุปภาพรวม Pre→Post + POE trend | E11: ไม่ต้องกรอก (Auto)
B12: 8 | C12: 🔗 POE-Fourtier เทียบ | D12: เทียบ gap ระหว่าง POE predict กับ Four-tier result | E12: ไม่ต้องกรอก (Auto)
B14: สีหมายถึง:
C15: เซลล์สีเหลือง = ต้องกรอกข้อมูลด้วยมือ
C16: เซลล์สีเขียว = คำนวณอัตโนมัติ ห้ามแก้ไข
C17: เซลล์สีแดง = พบ Misconception ชัดเจน
C18: เซลล์สีฟ้า = ข้อมูลอ้างอิง / หัวตาราง
B20: เกณฑ์การให้คะแนน POE Rubric
B21: คะแนน | C21: เกณฑ์ Predict (P) | D21: เกณฑ์ Explain (E) | E21: ความหมาย
B22: 0 | C22: ทำนายผิด | D22: อธิบายไม่เชื่อมกับ Observe | E22: ไม่มีการเปลี่ยนแปลงมโนทัศน์
B23: 1 | C23: ทำนายผิด | D23: อธิบายเชื่อมบางส่วน | E23: เริ่มเกิดความสงสัย (Cognitive Conflict)
B24: 2 | C24: ทำนายผิด | D24: อธิบายถูกต้องสมบูรณ์ | E24: มโนทัศน์เปลี่ยนแปลงได้ (Conceptual Change)
B25: 3 | C25: ทำนายถูก | D25: อธิบายถูกต้องสมบูรณ์ | E25: เข้าใจถูกต้องตั้งแต่ต้น (Sound Understanding)
B27: รูปแบบคำตอบ Four-tier → Auto-classification
B28: Tier1 | C28: Tier2 (มั่นใจ) | D28: Tier3 | E28: Tier4 (มั่นใจ) | F28: จำแนกเป็น | G28: ความหมาย
B29: ถูก | C29: มั่นใจ | D29: ถูก | E29: มั่นใจ | F29: ✅ Sound Understanding | G29: เข้าใจถูกต้องจริง
B30: ถูก | C30: มั่นใจ | D30: ผิด | E30: มั่นใจ | F30: 🎲 Lucky Guess | G30: เดาถูก (ไม่เข้าใจจริง)
B31: ผิด | C31: มั่นใจ | D31: ผิด | E31: มั่นใจ | F31: ❌ Misconception | G31: มโนทัศน์คลาดเคลื่อน
B32: ผิด | C32: ไม่มั่นใจ | D32: ผิด | E32: ไม่มั่นใจ | F32: ❓ Lack of Knowledge | G32: ขาดความรู้
B33: ถูก | C33: ไม่มั่นใจ | D33: ถูก | E33: ไม่มั่นใจ | F33: 🤔 Partial Understanding | G33: รู้บางส่วน ยังไม่มั่นใจ
B34: ผิด | C34: มั่นใจ | D34: ถูก | E34: มั่นใจ | F34: ⚠️ Mixed | G34: สับสน / ตอบขัดแย้ง

Sheet 📥 วาง Raw FT
B2: 📥 วิธีนำคะแนนจาก Google Sheet Database มาใส่ไฟล์นี้
B4: STEP 1 | C4: 📋 เตรียมรายชื่อ | D4: Copy student_id + ชื่อ + class จาก `StudentMaster` → paste ที่ Sheet `📥 ข้อมูลนักเรียน` คอลัมน์ B, C, E (เติม ม.5/4 35 คน · ม.5/5 7 คน default ให้แล้ว · ปรับได้)
B5: STEP 2 | C5: 🎯 รัน Auto-score ก่อน | D5: ใน Google Sheet → `🎯 Auto-score → 1️⃣ Score FT-01` + `2️⃣ Score FT-02` → จะได้ `FT01_Scored` / `FT02_Scored`
B6: STEP 3 | C6: 📝 วาง Four-tier (Pre) | D6: เปิด sheet `FT01` → เลือกคอลัมน์ q1_t1..q20_t4 (80 คอลัมน์ · คำตอบจริงของนักเรียน · ไม่ใช่ _cat) → Copy → มาที่ `📝 Four-tier กรอก` → วางที่เซลล์ **D7** (Pre-test นักเรียนคนแรก)
B7: STEP 4 | C7: 📝 วาง Four-tier (Post) | D7: sheet `FT02` → q1_t1..q20_t4 → วางที่ **D52** (Post-test block)
B8: STEP 5 | C8: 🔑 KEY ใส่ให้แล้ว | D8: KEY row 6 (Pre) + row 51 (Post) · 20 ข้อครบตาม `KEY_FT` จาก SHEET_FORMULAS.md · ถ้าแก้ข้อใด ให้แก้ในเซลล์สีเหลือง
B9: STEP 6 | C9: 🤖 ดูผลอัตโนมัติ | D9: เปิด `🤖 Four-tier วิเคราะห์` · `📊 สรุป Misconception` · `📈 Dashboard` → ระบบ classify Sound/MC/Guess/NoK ให้ทันที
B10: STEP 7 | C10: 🔬 POE (0-3) | D10: `🔬 POE บันทึก` → P-score + E-score ต่อแผน · copy จาก `POE_P{n}` column p_score/e_score หรือกรอกมือ · คะแนนรวมท้าย column AN/AO คำนวณอัตโนมัติ
B11: STEP 8 | C11: 📋 Formative F1-F9 | D11: `📋 Formative รายคาบ` → ข้อ 1-4 ต่อแผน · Pre+Post · paste จาก `F_Pre_P{n}` / `F_Post_P{n}` · อย่าลืมกรอก KEY แต่ละแผน (row 8 ของแต่ละ block)
B13: 🗺 Column Mapping · Google Sheet → ไฟล์นี้
B14: Google Sheet | C14: Column ต้นทาง | D14: ปลายทางในไฟล์นี้
B15: FT01 | C15: q1_t1 ถึง q20_t4 (80 cols) | D15: 📝 Four-tier กรอก · D7:CE46 (Pre)
B16: FT02 | C16: q1_t1 ถึง q20_t4 (80 cols) | D16: 📝 Four-tier กรอก · D52:CE91 (Post)
B17: POE_P1..P10 | C17: p_score, e_score (0-3) | D17: 🔬 POE บันทึก · D:AM ตามแผน
B18: F_Pre_P{n} | C18: q1_t1..q4_t4 (16 cols) | D18: 📋 Formative รายคาบ · Pre block
B19: F_Post_P{n} | C19: q1_t1..q4_t4 (16 cols) | D19: 📋 Formative รายคาบ · Post block
B20: StudentMaster | C20: student_id, name, class | D20: 📥 ข้อมูลนักเรียน · B, C, E
B23: 💡 Tips
B24: • ใช้ `Paste Special → Values Only` (Cmd+Shift+V) เพื่อไม่พา format จาก Google Sheet มาทับ
B25: • ถ้า Google Sheet มี timestamp/student_id นำหน้า → Copy เฉพาะ q1_t1 ไปขวามือ (ไม่รวม metadata ฝั่งซ้าย)
B26: • เรียงแถวนักเรียนให้ตรงกันทั้ง Pre และ Post (ใช้ student_id sort ก่อน copy)
B27: • T2/T4 ในฐานข้อมูลเป็นตัวเลข 1-5 → ไฟล์นี้ใช้ Y/N · ใช้สูตรแปลง =IF(N>=4,"Y","N") ในคอลัมน์ช่วยก่อน paste
B28: • ถ้านักเรียน > 42 คน ต่อห้อง → ขยาย row ใน Sheet `📥 ข้อมูลนักเรียน` (copy สูตรลงมา)

Sheet 📥 ข้อมูลนักเรียน
B1: ข้อมูลพื้นฐานนักเรียน — กรอกครั้งเดียว ใช้ได้ทุก Sheet
B2: ⚠️ กรอกข้อมูลในเซลล์สีเหลืองเท่านั้น | ห้ามลบหรือแก้ไขแถวหัวตาราง
A3: ที่ | B3: เลขที่ | C3: ชื่อ-สกุลนักเรียน | D3: เพศ | E3: กลุ่มเรียน | F3: Pre-test (คะแนนเต็ม 20) | G3: Post-test (คะแนนเต็ม 20) | H3: หมายเหตุ
A4: 1 | E4: ม.5/4
A5: 2 | E5: ม.5/4
A6: 3 | E6: ม.5/4
A7: 4 | E7: ม.5/4
A8: 5 | E8: ม.5/4
A9: 6 | E9: ม.5/4
A10: 7 | E10: ม.5/4
A11: 8 | E11: ม.5/4
A12: 9 | E12: ม.5/4
A13: 10 | E13: ม.5/4
A14: 11 | E14: ม.5/4
A15: 12 | E15: ม.5/4
... A43: 40 | E43: ม.5/5
B44: สรุป (Auto) | F44: =IFERROR(AVERAGE(F4:F43),"—") | G44: =IFERROR(AVERAGE(G4:G43),"—")
B45: จำนวนนักเรียนทั้งหมด | F45: =COUNTA(C4:C43) | G45: =COUNTA(G4:G43)

Sheet 🔬 POE บันทึก
B1: 🔬 บันทึกคะแนน POE — กรอกคะแนน 0–3 ตามเกณฑ์ใน Sheet คำแนะนำ
B2: ที่ | C2: ชื่อนักเรียน | D2: แผนที่ 1 | J2: แผนที่ 2 | P2: แผนที่ 3 | T2: แผนที่ 4 | V2: แผนที่ 5 | Z2: แผนที่ 6 | AD2: แผนที่ 7 | AH2: แผนที่ 8 | AJ2: แผนที่ 9 | AL2: แผนที่ 10
B3: ที่ | C3: ชื่อนักเรียน | D3: แผน1 สปริง P1 (P) | E3: แผน1 สปริง P1 (รวม) | F3: แผน1 สปริง P2 (P) | G3: แผน1 สปริง P2 (รวม) | H3: แผน1 PhET P1 (P) | I3: แผน1 PhET P1 (รวม) | J3: แผน2 กราฟ P1 (P) | K3: แผน2 กราฟ P1 (รวม) | L3: แผน2 PhET P2 (P) | M3: แผน2 PhET P2 (รวม) | N3: แผน2 เฟส P3 (P) | O3: แผน2 เฟส P3 (รวม) | P3: แผน3 เชือก P1 (P) | Q3: แผน3 เชือก P1 (รวม) | R3: แผน3 v=fλ P2 (P) | S3: แผน3 v=fλ P2 (รวม) | T3: แผน4 คำนวณ P1 (P) | U3: แผน4 คำนวณ P1 (รวม) | V3: แผน5 ฮอย P1 (P) | W3: แผน5 ฮอย P1 (รวม) | X3: แผน5 ซ้อน P2 (P) | Y3: แผน5 ซ้อน P2 (รวม) | Z3: แผน6 สะท้อน P1 (P) | AA3: แผน6 สะท้อน P1 (รวม) | AB3: แผน6 หักเห P2 (P) | AC3: แผน6 หักเห P2 (รวม) | AD3: แผน7 แทรก P1 (P) | AE3: แผน7 แทรก P1 (รวม) | AF3: แผน7 นิ่ง P2 (P) | AG3: แผน7 นิ่ง P2 (รวม) | AH3: แผน8 เลี้ยว P1 (P) | AI3: แผน8 เลี้ยว P1 (รวม) | AJ3: แผน9 บูรณา P1 (P) | AK3: แผน9 บูรณา P1 (รวม) | AL3: แผน10 ทบทวน P1 (P) | AM3: แผน10 ทบทวน P1 (รวม) | AN3: คะแนน รวม POE | AO3: เฉลี่ย รวม
B4: ='📥 ข้อมูลนักเรียน'!B4 | C4: ='📥 ข้อมูลนักเรียน'!C4 | AN4: =SUM(D4,E4,F4,G4,H4,I4,J4,K4,L4,M4,N4,O4,P4,Q4,R4,S4,T4,U4,V4,W4,X4,Y4,Z4,AA4,AB4,AC4,AD4,AE4,AF4,AG4,AH4,AI4,AJ4,AK4,AL4,AM4) | AO4: =IFERROR(AN4/36,0)
B5: ='📥 ข้อมูลนักเรียน'!B5 | C5: ='📥 ข้อมูลนักเรียน'!C5 | AN5: =SUM(D5,E5,F5,G5,H5,I5,J5,K5,L5,M5,N5,O5,P5,Q5,R5,S5,T5,U5,V5,W5,X5,Y5,Z5,AA5,AB5,AC5,AD5,AE5,AF5,AG5,AH5,AI5,AJ5,AK5,AL5,AM5) | AO5: =IFERROR(AN5/36,0)
B6: ='📥 ข้อมูลนักเรียน'!B6 | C6: ='📥 ข้อมูลนักเรียน'!C6 | AN6: =SUM(D6,E6,F6,G6,H6,I6,J6,K6,L6,M6,N6,O6,P6,Q6,R6,S6,T6,U6,V6,W6,X6,Y6,Z6,AA6,AB6,AC6,AD6,AE6,AF6,AG6,AH6,AI6,AJ6,AK6,AL6,AM6) | AO6: =IFERROR(AN6/36,0)
B7: ='📥 ข้อมูลนักเรียน'!B7 | C7: ='📥 ข้อมูลนักเรียน'!C7 | AN7: =SUM(D7,E7,F7,G7,H7,I7,J7,K7,L7,M7,N7,O7,P7,Q7,R7,S7,T7,U7,V7,W7,X7,Y7,Z7,AA7,AB7,AC7,AD7,AE7,AF7,AG7,AH7,AI7,AJ7,AK7,AL7,AM7) | AO7: =IFERROR(AN7/36,0)
B8: ='📥 ข้อมูลนักเรียน'!B8 | C8: ='📥 ข้อมูลนักเรียน'!C8 | AN8: =SUM(D8,E8,F8,G8,H8,I8,J8,K8,L8,M8,N8,O8,P8,Q8,R8,S8,T8,U8,V8,W8,X8,Y8,Z8,AA8,AB8,AC8,AD8,AE8,AF8,AG8,AH8,AI8,AJ8,AK8,AL8,AM8) | AO8: =IFERROR(AN8/36,0)
B9: ='📥 ข้อมูลนักเรียน'!B9 | C9: ='📥 ข้อมูลนักเรียน'!C9 | AN9: =SUM(D9,E9,F9,G9,H9,I9,J9,K9,L9,M9,N9,O9,P9,Q9,R9,S9,T9,U9,V9,W9,X9,Y9,Z9,AA9,AB9,AC9,AD9,AE9,AF9,AG9,AH9,AI9,AJ9,AK9,AL9,AM9) | AO9: =IFERROR(AN9/36,0)
B10: ='📥 ข้อมูลนักเรียน'!B10 | C10: ='📥 ข้อมูลนักเรียน'!C10 | AN10: =SUM(D10,E10,F10,G10,H10,I10,J10,K10,L10,M10,N10,O10,P10,Q10,R10,S10,T10,U10,V10,W10,X10,Y10,Z10,AA10,AB10,AC10,AD10,AE10,AF10,AG10,AH10,AI10,AJ10,AK10,AL10,AM10) | AO10: =IFERROR(AN10/36,0)
B11: ='📥 ข้อมูลนักเรียน'!B11 | C11: ='📥 ข้อมูลนักเรียน'!C11 | AN11: =SUM(D11,E11,F11,G11,H11,I11,J11,K11,L11,M11,N11,O11,P11,Q11,R11,S11,T11,U11,V11,W11,X11,Y11,Z11,AA11,AB11,AC11,AD11,AE11,AF11,AG11,AH11,AI11,AJ11,AK11,AL11,AM11) | AO11: =IFERROR(AN11/36,0)
B12: ='📥 ข้อมูลนักเรียน'!B12 | C12: ='📥 ข้อมูลนักเรียน'!C12 | AN12: =SUM(D12,E12,F12,G12,H12,I12,J12,K12,L12,M12,N12,O12,P12,Q12,R12,S12,T12,U12,V12,W12,X12,Y12,Z12,AA12,AB12,AC12,AD12,AE12,AF12,AG12,AH12,AI12,AJ12,AK12,AL12,AM12) | AO12: =IFERROR(AN12/36,0)
B13: ='📥 ข้อมูลนักเรียน'!B13 | C13: ='📥 ข้อมูลนักเรียน'!C13 | AN13: =SUM(D13,E13,F13,G13,H13,I13,J13,K13,L13,M13,N13,O13,P13,Q13,R13,S13,T13,U13,V13,W13,X13,Y13,Z13,AA13,AB13,AC13,AD13,AE13,AF13,AG13,AH13,AI13,AJ13,AK13,AL13,AM13) | AO13: =IFERROR(AN13/36,0)
B14: ='📥 ข้อมูลนักเรียน'!B14 | C14: ='📥 ข้อมูลนักเรียน'!C14 | AN14: =SUM(D14,E14,F14,G14,H14,I14,J14,K14,L14,M14,N14,O14,P14,Q14,R14,S14,T14,U14,V14,W14,X14,Y14,Z14,AA14,AB14,AC14,AD14,AE14,AF14,AG14,AH14,AI14,AJ14,AK14,AL14,AM14) | AO14: =IFERROR(AN14/36,0)
B15: ='📥 ข้อมูลนักเรียน'!B15 | C15: ='📥 ข้อมูลนักเรียน'!C15 | AN15: =SUM(D15,E15,F15,G15,H15,I15,J15,K15,L15,M15,N15,O15,P15,Q15,R15,S15,T15,U15,V15,W15,X15,Y15,Z15,AA15,AB15,AC15,AD15,AE15,AF15,AG15,AH15,AI15,AJ15,AK15,AL15,AM15) | AO15: =IFERROR(AN15/36,0)
... B43: ='📥 ข้อมูลนักเรียน'!B43 | C43: ='📥 ข้อมูลนักเรียน'!C43 | AN43: =SUM(D43,E43,F43,G43,H43,I43,J43,K43,L43,M43,N43,O43,P43,Q43,R43,S43,T43,U43,V43,W43,X43,Y43,Z43,AA43,AB43,AC43,AD43,AE43,AF43,AG43,AH43,AI43,AJ43,AK43,AL43,AM43) | AO43: =IFERROR(AN43/36,0)

Sheet 📋 Formative รายคาบ
B1: 📋 Formative Test รายคาบ — Four-tier (Tier 1–4) | 4 ข้อ/แผน | Pre+Post | วัด Misconception รายแผน
B2: T1,T3: กรอก ก/ข/ค/ง | T2,T4: Y=มั่นใจ N=ไม่มั่นใจ | 🟡 ช่องสีเหลือง=กรอก 🟢 ช่องสีเขียว=Auto | แผน 4,8,9 ไม่มี Pre-test (Post only)
B3: ▌ แผนที่ 1 | คาบที่ 1–2 | Misconception: M1, M3 | ข้อที่ 1–4
B4: 📍 M1: อนุภาคน้ำเคลื่อนตามคลื่น | M3: เสียงเป็นคลื่นตามขวาง
B5: 🔵 PRE-test — ก่อนสอน (แผน 1 ข้อ 1–4)
B6: ที่ | C6: ชื่อนักเรียน | D6: ข้อ 1 | H6: ข้อ 2 | L6: ข้อ 3 | P6: ข้อ 4 | T6: Sound ✅ | U6: Misc ❌ | V6: Guess 🎲 | W6: NoK ❓ | X6: % Misc (Auto)
C7: ← กรอกเฉลย T1 และ T3 | D7: T1 (ก-ง) | E7: T2 (Y/N) | F7: T3 (ก-ง) | G7: T4 (Y/N) | H7: T1 (ก-ง) | I7: T2 (Y/N) | J7: T3 (ก-ง) | K7: T4 (Y/N) | L7: T1 (ก-ง) | M7: T2 (Y/N) | N7: T3 (ก-ง) | O7: T4 (Y/N) | P7: T1 (ก-ง) | Q7: T2 (Y/N) | R7: T3 (ก-ง) | S7: T4 (Y/N) | T7: — | U7: — | V7: — | W7: — | X7: —
B8: KEY | C8: ← กรอกเฉลยที่ถูกต้อง | E8: — | G8: — | I8: — | K8: — | M8: — | O8: — | Q8: — | S8: — | T8: — | U8: — | V8: — | W8: — | X8: —
B9: ='📥 ข้อมูลนักเรียน'!B4 | C9: ='📥 ข้อมูลนักเรียน'!C4 | T9: =IFERROR(SUMPRODUCT(((D9=D8)*(E9="Y")*(F9=F8)*(G9="Y")*(D9<>"")* (F9<>""))+((H9=H8)*(I9="Y")*(J9=J8)*(K9="Y")*(H9<>"")* (J9<>""))+((L9=L8)*(M9="Y")*(N9=N8)*(O9="Y")*(L9<>"")* (N9<>""))+((P9=P8)*(Q9="Y")*(R9=R8)*(S9="Y")*(P9<>"")* (R9<>""))),0) | U9: =IFERROR(SUMPRODUCT(((D9<>D8)*(E9="Y")*(F9<>F8)*(G9="Y")*(D9<>"")* (F9<>""))+((H9<>H8)*(I9="Y")*(J9<>J8)*(K9="Y")*(H9<>"")* (J9<>""))+((L9<>L8)*(M9="Y")*(N9<>N8)*(O9="Y")*(L9<>"")* (N9<>""))+((P9<>P8)*(Q9="Y")*(R9<>R8)*(S9="Y")*(P9<>"")* (R9<>""))),0) | V9: =IFERROR(SUMPRODUCT(((D9=D8)*(E9="Y")*(F9<>F8)*(G9="Y")*(D9<>"")* (F9<>""))+((H9=H8)*(I9="Y")*(J9<>J8)*(K9="Y")*(H9<>"")* (J9<>""))+((L9=L8)*(M9="Y")*(N9<>N8)*(O9="Y")*(L9<>"")* (N9<>""))+((P9=P8)*(Q9="Y")*(R9<>R8)*(S9="Y")*(P9<>"")* (R9<>""))),0) | W9: =IFERROR(SUMPRODUCT(((E9="N")*(D9<>"")* (F9<>""))+((I9="N")*(H9<>"")* (J9<>""))+((M9="N")*(L9<>"")* (N9<>""))+((Q9="N")*(P9<>"")* (R9<>""))),0) | X9: =IFERROR(U9/4,0)
B10: ='📥 ข้อมูลนักเรียน'!B5 | C10: ='📥 ข้อมูลนักเรียน'!C5 | T10: =IFERROR(SUMPRODUCT(((D10=D8)*(E10="Y")*(F10=F8)*(G10="Y")*(D10<>"")* (F10<>""))+((H10=H8)*(I10="Y")*(J10=J8)*(K10="Y")*(H10<>"")* (J10<>""))+((L10=L8)*(M10="Y")*(N10=N8)*(O10="Y")*(L10<>"")* (N10<>""))+((P10=P8)*(Q10="Y")*(R10=R8)*(S10="Y")*(P10<>"")* (R10<>""))),0) | U10: =IFERROR(SUMPRODUCT(((D10<>D8)*(E10="Y")*(F10<>F8)*(G10="Y")*(D10<>"")* (F10<>""))+((H10<>H8)*(I10="Y")*(J10<>J8)*(K10="Y")*(H10<>"")* (J10<>""))+((L10<>L8)*(M10="Y")*(N10<>N8)*(O10="Y")*(L10<>"")* (N10<>""))+((P10<>P8)*(Q10="Y")*(R10<>R8)*(S10="Y")*(P10<>"")* (R10<>""))),0) | V10: =IFERROR(SUMPRODUCT(((D10=D8)*(E10="Y")*(F10<>F8)*(G10="Y")*(D10<>"")* (F10<>""))+((H10=H8)*(I10="Y")*(J10<>J8)*(K10="Y")*(H10<>"")* (J10<>""))+((L10=L8)*(M10="Y")*(N10<>N8)*(O10="Y")*(L10<>"")* (N10<>""))+((P10=P8)*(Q10="Y")*(R10<>R8)*(S10="Y")*(P10<>"")* (R10<>""))),0) | W10: =IFERROR(SUMPRODUCT(((E10="N")*(D10<>"")* (F10<>""))+((I10="N")*(H10<>"")* (J10<>""))+((M10="N")*(L10<>"")* (N10<>""))+((Q10="N")*(P10<>"")* (R10<>""))),0) | X10: =IFERROR(U10/4,0)
B11: ='📥 ข้อมูลนักเรียน'!B6 | C11: ='📥 ข้อมูลนักเรียน'!C6 | T11: =IFERROR(SUMPRODUCT(((D11=D8)*(E11="Y")*(F11=F8)*(G11="Y")*(D11<>"")* (F11<>""))+((H11=H8)*(I11="Y")*(J11=J8)*(K11="Y")*(H11<>"")* (J11<>""))+((L11=L8)*(M11="Y")*(N11=N8)*(O11="Y")*(L11<>"")* (N11<>""))+((P11=P8)*(Q11="Y")*(R11=R8)*(S11="Y")*(P11<>"")* (R11<>""))),0) | U11: =IFERROR(SUMPRODUCT(((D11<>D8)*(E11="Y")*(F11<>F8)*(G11="Y")*(D11<>"")* (F11<>""))+((H11<>H8)*(I11="Y")*(J11<>J8)*(K11="Y")*(H11<>"")* (J11<>""))+((L11<>L8)*(M11="Y")*(N11<>N8)*(O11="Y")*(L11<>"")* (N11<>""))+((P11<>P8)*(Q11="Y")*(R11<>R8)*(S11="Y")*(P11<>"")* (R11<>""))),0) | V11: =IFERROR(SUMPRODUCT(((D11=D8)*(E11="Y")*(F11<>F8)*(G11="Y")*(D11<>"")* (F11<>""))+((H11=H8)*(I11="Y")*(J11<>J8)*(K11="Y")*(H11<>"")* (J11<>""))+((L11=L8)*(M11="Y")*(N11<>N8)*(O11="Y")*(L11<>"")* (N11<>""))+((P11=P8)*(Q11="Y")*(R11<>R8)*(S11="Y")*(P11<>"")* (R11<>""))),0) | W11: =IFERROR(SUMPRODUCT(((E11="N")*(D11<>"")* (F11<>""))+((I11="N")*(H11<>"")* (J11<>""))+((M11="N")*(L11<>"")* (N11<>""))+((Q11="N")*(P11<>"")* (R11<>""))),0) | X11: =IFERROR(U11/4,0)
B12: ='📥 ข้อมูลนักเรียน'!B7 | C12: ='📥 ข้อมูลนักเรียน'!C7 | T12: =IFERROR(SUMPRODUCT(((D12=D8)*(E12="Y")*(F12=F8)*(G12="Y")*(D12<>"")* (F12<>""))+((H12=H8)*(I12="Y")*(J12=J8)*(K12="Y")*(H12<>"")* (J12<>""))+((L12=L8)*(M12="Y")*(N12=N8)*(O12="Y")*(L12<>"")* (N12<>""))+((P12=P8)*(Q12="Y")*(R12=R8)*(S12="Y")*(P12<>"")* (R12<>""))),0) | U12: =IFERROR(SUMPRODUCT(((D12<>D8)*(E12="Y")*(F12<>F8)*(G12="Y")*(D12<>"")* (F12<>""))+((H12<>H8)*(I12="Y")*(J12<>J8)*(K12="Y")*(H12<>"")* (J12<>""))+((L12<>L8)*(M12="Y")*(N12<>N8)*(O12="Y")*(L12<>"")* (N12<>""))+((P12<>P8)*(Q12="Y")*(R12<>R8)*(S12="Y")*(P12<>"")* (R12<>""))),0) | V12: =IFERROR(SUMPRODUCT(((D12=D8)*(E12="Y")*(F12<>F8)*(G12="Y")*(D12<>"")* (F12<>""))+((H12=H8)*(I12="Y")*(J12<>J8)*(K12="Y")*(H12<>"")* (J12<>""))+((L12=L8)*(M12="Y")*(N12<>N8)*(O12="Y")*(L12<>"")* (N12<>""))+((P12=P8)*(Q12="Y")*(R12<>R8)*(S12="Y")*(P12<>"")* (R12<>""))),0) | W12: =IFERROR(SUMPRODUCT(((E12="N")*(D12<>"")* (F12<>""))+((I12="N")*(H12<>"")* (J12<>""))+((M12="N")*(L12<>"")* (N12<>""))+((Q12="N")*(P12<>"")* (R12<>""))),0) | X12: =IFERROR(U12/4,0)
B13: ='📥 ข้อมูลนักเรียน'!B8 | C13: ='📥 ข้อมูลนักเรียน'!C8 | T13: =IFERROR(SUMPRODUCT(((D13=D8)*(E13="Y")*(F13=F8)*(G13="Y")*(D13<>"")* (F13<>""))+((H13=H8)*(I13="Y")*(J13=J8)*(K13="Y")*(H13<>"")* (J13<>""))+((L13=L8)*(M13="Y")*(N13=N8)*(O13="Y")*(L13<>"")* (N13<>""))+((P13=P8)*(Q13="Y")*(R13=R8)*(S13="Y")*(P13<>"")* (R13<>""))),0) | U13: =IFERROR(SUMPRODUCT(((D13<>D8)*(E13="Y")*(F13<>F8)*(G13="Y")*(D13<>"")* (F13<>""))+((H13<>H8)*(I13="Y")*(J13<>J8)*(K13="Y")*(H13<>"")* (J13<>""))+((L13<>L8)*(M13="Y")*(N13<>N8)*(O13="Y")*(L13<>"")* (N13<>""))+((P13<>P8)*(Q13="Y")*(R13<>R8)*(S13="Y")*(P13<>"")* (R13<>""))),0) | V13: =IFERROR(SUMPRODUCT(((D13=D8)*(E13="Y")*(F13<>F8)*(G13="Y")*(D13<>"")* (F13<>""))+((H13=H8)*(I13="Y")*(J13<>J8)*(K13="Y")*(H13<>"")* (J13<>""))+((L13=L8)*(M13="Y")*(N13<>N8)*(O13="Y")*(L13<>"")* (N13<>""))+((P13=P8)*(Q13="Y")*(R13<>R8)*(S13="Y")*(P13<>"")* (R13<>""))),0) | W13: =IFERROR(SUMPRODUCT(((E13="N")*(D13<>"")* (F13<>""))+((I13="N")*(H13<>"")* (J13<>""))+((M13="N")*(L13<>"")* (N13<>""))+((Q13="N")*(P13<>"")* (R13<>""))),0) | X13: =IFERROR(U13/4,0)
B14: ='📥 ข้อมูลนักเรียน'!B9 | C14: ='📥 ข้อมูลนักเรียน'!C9 | T14: =IFERROR(SUMPRODUCT(((D14=D8)*(E14="Y")*(F14=F8)*(G14="Y")*(D14<>"")* (F14<>""))+((H14=H8)*(I14="Y")*(J14=J8)*(K14="Y")*(H14<>"")* (J14<>""))+((L14=L8)*(M14="Y")*(N14=N8)*(O14="Y")*(L14<>"")* (N14<>""))+((P14=P8)*(Q14="Y")*(R14=R8)*(S14="Y")*(P14<>"")* (R14<>""))),0) | U14: =IFERROR(SUMPRODUCT(((D14<>D8)*(E14="Y")*(F14<>F8)*(G14="Y")*(D14<>"")* (F14<>""))+((H14<>H8)*(I14="Y")*(J14<>J8)*(K14="Y")*(H14<>"")* (J14<>""))+((L14<>L8)*(M14="Y")*(N14<>N8)*(O14="Y")*(L14<>"")* (N14<>""))+((P14<>P8)*(Q14="Y")*(R14<>R8)*(S14="Y")*(P14<>"")* (R14<>""))),0) | V14: =IFERROR(SUMPRODUCT(((D14=D8)*(E14="Y")*(F14<>F8)*(G14="Y")*(D14<>"")* (F14<>""))+((H14=H8)*(I14="Y")*(J14<>J8)*(K14="Y")*(H14<>"")* (J14<>""))+((L14=L8)*(M14="Y")*(N14<>N8)*(O14="Y")*(L14<>"")* (N14<>""))+((P14=P8)*(Q14="Y")*(R14<>R8)*(S14="Y")*(P14<>"")* (R14<>""))),0) | W14: =IFERROR(SUMPRODUCT(((E14="N")*(D14<>"")* (F14<>""))+((I14="N")*(H14<>"")* (J14<>""))+((M14="N")*(L14<>"")* (N14<>""))+((Q14="N")*(P14<>"")* (R14<>""))),0) | X14: =IFERROR(U14/4,0)
B15: ='📥 ข้อมูลนักเรียน'!B10 | C15: ='📥 ข้อมูลนักเรียน'!C10 | T15: =IFERROR(SUMPRODUCT(((D15=D8)*(E15="Y")*(F15=F8)*(G15="Y")*(D15<>"")* (F15<>""))+((H15=H8)*(I15="Y")*(J15=J8)*(K15="Y")*(H15<>"")* (J15<>""))+((L15=L8)*(M15="Y")*(N15=N8)*(O15="Y")*(L15<>"")* (N15<>""))+((P15=P8)*(Q15="Y")*(R15=R8)*(S15="Y")*(P15<>"")* (R15<>""))),0) | U15: =IFERROR(SUMPRODUCT(((D15<>D8)*(E15="Y")*(F15<>F8)*(G15="Y")*(D15<>"")* (F15<>""))+((H15<>H8)*(I15="Y")*(J15<>J8)*(K15="Y")*(H15<>"")* (J15<>""))+((L15<>L8)*(M15="Y")*(N15<>N8)*(O15="Y")*(L15<>"")* (N15<>""))+((P15<>P8)*(Q15="Y")*(R15<>R8)*(S15="Y")*(P15<>"")* (R15<>""))),0) | V15: =IFERROR(SUMPRODUCT(((D15=D8)*(E15="Y")*(F15<>F8)*(G15="Y")*(D15<>"")* (F15<>""))+((H15=H8)*(I15="Y")*(J15<>J8)*(K15="Y")*(H15<>"")* (J15<>""))+((L15=L8)*(M15="Y")*(N15<>N8)*(O15="Y")*(L15<>"")* (N15<>""))+((P15=P8)*(Q15="Y")*(R15<>R8)*(S15="Y")*(P15<>"")* (R15<>""))),0) | W15: =IFERROR(SUMPRODUCT(((E15="N")*(D15<>"")* (F15<>""))+((I15="N")*(H15<>"")* (J15<>""))+((M15="N")*(L15<>"")* (N15<>""))+((Q15="N")*(P15<>"")* (R15<>""))),0) | X15: =IFERROR(U15/4,0)
B16: ='📥 ข้อมูลนักเรียน'!B11 | C16: ='📥 ข้อมูลนักเรียน'!C11 | T16: =IFERROR(SUMPRODUCT(((D16=D8)*(E16="Y")*(F16=F8)*(G16="Y")*(D16<>"")* (F16<>""))+((H16=H8)*(I16="Y")*(J16=J8)*(K16="Y")*(H16<>"")* (J16<>""))+((L16=L8)*(M16="Y")*(N16=N8)*(O16="Y")*(L16<>"")* (N16<>""))+((P16=P8)*(Q16="Y")*(R16=R8)*(S16="Y")*(P16<>"")* (R16<>""))),0) | U16: =IFERROR(SUMPRODUCT(((D16<>D8)*(E16="Y")*(F16<>F8)*(G16="Y")*(D16<>"")* (F16<>""))+((H16<>H8)*(I16="Y")*(J16<>J8)*(K16="Y")*(H16<>"")* (J16<>""))+((L16<>L8)*(M16="Y")*(N16<>N8)*(O16="Y")*(L16<>"")* (N16<>""))+((P16<>P8)*(Q16="Y")*(R16<>R8)*(S16="Y")*(P16<>"")* (R16<>""))),0) | V16: =IFERROR(SUMPRODUCT(((D16=D8)*(E16="Y")*(F16<>F8)*(G16="Y")*(D16<>"")* (F16<>""))+((H16=H8)*(I16="Y")*(J16<>J8)*(K16="Y")*(H16<>"")* (J16<>""))+((L16=L8)*(M16="Y")*(N16<>N8)*(O16="Y")*(L16<>"")* (N16<>""))+((P16=P8)*(Q16="Y")*(R16<>R8)*(S16="Y")*(P16<>"")* (R16<>""))),0) | W16: =IFERROR(SUMPRODUCT(((E16="N")*(D16<>"")* (F16<>""))+((I16="N")*(H16<>"")* (J16<>""))+((M16="N")*(L16<>"")* (N16<>""))+((Q16="N")*(P16<>"")* (R16<>""))),0) | X16: =IFERROR(U16/4,0)
B17: ='📥 ข้อมูลนักเรียน'!B12 | C17: ='📥 ข้อมูลนักเรียน'!C12 | T17: =IFERROR(SUMPRODUCT(((D17=D8)*(E17="Y")*(F17=F8)*(G17="Y")*(D17<>"")* (F17<>""))+((H17=H8)*(I17="Y")*(J17=J8)*(K17="Y")*(H17<>"")* (J17<>""))+((L17=L8)*(M17="Y")*(N17=N8)*(O17="Y")*(L17<>"")* (N17<>""))+((P17=P8)*(Q17="Y")*(R17=R8)*(S17="Y")*(P17<>"")* (R17<>""))),0) | U17: =IFERROR(SUMPRODUCT(((D17<>D8)*(E17="Y")*(F17<>F8)*(G17="Y")*(D17<>"")* (F17<>""))+((H17<>H8)*(I17="Y")*(J17<>J8)*(K17="Y")*(H17<>"")* (J17<>""))+((L17<>L8)*(M17="Y")*(N17<>N8)*(O17="Y")*(L17<>"")* (N17<>""))+((P17<>P8)*(Q17="Y")*(R17<>R8)*(S17="Y")*(P17<>"")* (R17<>""))),0) | V17: =IFERROR(SUMPRODUCT(((D17=D8)*(E17="Y")*(F17<>F8)*(G17="Y")*(D17<>"")* (F17<>""))+((H17=H8)*(I17="Y")*(J17<>J8)*(K17="Y")*(H17<>"")* (J17<>""))+((L17=L8)*(M17="Y")*(N17<>N8)*(O17="Y")*(L17<>"")* (N17<>""))+((P17=P8)*(Q17="Y")*(R17<>R8)*(S17="Y")*(P17<>"")* (R17<>""))),0) | W17: =IFERROR(SUMPRODUCT(((E17="N")*(D17<>"")* (F17<>""))+((I17="N")*(H17<>"")* (J17<>""))+((M17="N")*(L17<>"")* (N17<>""))+((Q17="N")*(P17<>"")* (R17<>""))),0) | X17: =IFERROR(U17/4,0)
B18: ='📥 ข้อมูลนักเรียน'!B13 | C18: ='📥 ข้อมูลนักเรียน'!C13 | T18: =IFERROR(SUMPRODUCT(((D18=D8)*(E18="Y")*(F18=F8)*(G18="Y")*(D18<>"")* (F18<>""))+((H18=H8)*(I18="Y")*(J18=J8)*(K18="Y")*(H18<>"")* (J18<>""))+((L18=L8)*(M18="Y")*(N18=N8)*(O18="Y")*(L18<>"")* (N18<>""))+((P18=P8)*(Q18="Y")*(R18=R8)*(S18="Y")*(P18<>"")* (R18<>""))),0) | U18: =IFERROR(SUMPRODUCT(((D18<>D8)*(E18="Y")*(F18<>F8)*(G18="Y")*(D18<>"")* (F18<>""))+((H18<>H8)*(I18="Y")*(J18<>J8)*(K18="Y")*(H18<>"")* (J18<>""))+((L18<>L8)*(M18="Y")*(N18<>N8)*(O18="Y")*(L18<>"")* (N18<>""))+((P18<>P8)*(Q18="Y")*(R18<>R8)*(S18="Y")*(P18<>"")* (R18<>""))),0) | V18: =IFERROR(SUMPRODUCT(((D18=D8)*(E18="Y")*(F18<>F8)*(G18="Y")*(D18<>"")* (F18<>""))+((H18=H8)*(I18="Y")*(J18<>J8)*(K18="Y")*(H18<>"")* (J18<>""))+((L18=L8)*(M18="Y")*(N18<>N8)*(O18="Y")*(L18<>"")* (N18<>""))+((P18=P8)*(Q18="Y")*(R18<>R8)*(S18="Y")*(P18<>"")* (R18<>""))),0) | W18: =IFERROR(SUMPRODUCT(((E18="N")*(D18<>"")* (F18<>""))+((I18="N")*(H18<>"")* (J18<>""))+((M18="N")*(L18<>"")* (N18<>""))+((Q18="N")*(P18<>"")* (R18<>""))),0) | X18: =IFERROR(U18/4,0)
B19: ='📥 ข้อมูลนักเรียน'!B14 | C19: ='📥 ข้อมูลนักเรียน'!C14 | T19: =IFERROR(SUMPRODUCT(((D19=D8)*(E19="Y")*(F19=F8)*(G19="Y")*(D19<>"")* (F19<>""))+((H19=H8)*(I19="Y")*(J19=J8)*(K19="Y")*(H19<>"")* (J19<>""))+((L19=L8)*(M19="Y")*(N19=N8)*(O19="Y")*(L19<>"")* (N19<>""))+((P19=P8)*(Q19="Y")*(R19=R8)*(S19="Y")*(P19<>"")* (R19<>""))),0) | U19: =IFERROR(SUMPRODUCT(((D19<>D8)*(E19="Y")*(F19<>F8)*(G19="Y")*(D19<>"")* (F19<>""))+((H19<>H8)*(I19="Y")*(J19<>J8)*(K19="Y")*(H19<>"")* (J19<>""))+((L19<>L8)*(M19="Y")*(N19<>N8)*(O19="Y")*(L19<>"")* (N19<>""))+((P19<>P8)*(Q19="Y")*(R19<>R8)*(S19="Y")*(P19<>"")* (R19<>""))),0) | V19: =IFERROR(SUMPRODUCT(((D19=D8)*(E19="Y")*(F19<>F8)*(G19="Y")*(D19<>"")* (F19<>""))+((H19=H8)*(I19="Y")*(J19<>J8)*(K19="Y")*(H19<>"")* (J19<>""))+((L19=L8)*(M19="Y")*(N19<>N8)*(O19="Y")*(L19<>"")* (N19<>""))+((P19=P8)*(Q19="Y")*(R19<>R8)*(S19="Y")*(P19<>"")* (R19<>""))),0) | W19: =IFERROR(SUMPRODUCT(((E19="N")*(D19<>"")* (F19<>""))+((I19="N")*(H19<>"")* (J19<>""))+((M19="N")*(L19<>"")* (N19<>""))+((Q19="N")*(P19<>"")* (R19<>""))),0) | X19: =IFERROR(U19/4,0)
B20: ='📥 ข้อมูลนักเรียน'!B15 | C20: ='📥 ข้อมูลนักเรียน'!C15 | T20: =IFERROR(SUMPRODUCT(((D20=D8)*(E20="Y")*(F20=F8)*(G20="Y")*(D20<>"")* (F20<>""))+((H20=H8)*(I20="Y")*(J20=J8)*(K20="Y")*(H20<>"")* (J20<>""))+((L20=L8)*(M20="Y")*(N20=N8)*(O20="Y")*(L20<>"")* (N20<>""))+((P20=P8)*(Q20="Y")*(R20=R8)*(S20="Y")*(P20<>"")* (R20<>""))),0) | U20: =IFERROR(SUMPRODUCT(((D20<>D8)*(E20="Y")*(F20<>F8)*(G20="Y")*(D20<>"")* (F20<>""))+((H20<>H8)*(I20="Y")*(J20<>J8)*(K20="Y")*(H20<>"")* (J20<>""))+((L20<>L8)*(M20="Y")*(N20<>N8)*(O20="Y")*(L20<>"")* (N20<>""))+((P20<>P8)*(Q20="Y")*(R20<>R8)*(S20="Y")*(P20<>"")* (R20<>""))),0) | V20: =IFERROR(SUMPRODUCT(((D20=D8)*(E20="Y")*(F20<>F8)*(G20="Y")*(D20<>"")* (F20<>""))+((H20=H8)*(I20="Y")*(J20<>J8)*(K20="Y")*(H20<>"")* (J20<>""))+((L20=L8)*(M20="Y")*(N20<>N8)*(O20="Y")*(L20<>"")* (N20<>""))+((P20=P8)*(Q20="Y")*(R20<>R8)*(S20="Y")*(P20<>"")* (R20<>""))),0) | W20: =IFERROR(SUMPRODUCT(((E20="N")*(D20<>"")* (F20<>""))+((I20="N")*(H20<>"")* (J20<>""))+((M20="N")*(L20<>"")* (N20<>""))+((Q20="N")*(P20<>"")* (R20<>""))),0) | X20: =IFERROR(U20/4,0)
B21: ='📥 ข้อมูลนักเรียน'!B16 | C21: ='📥 ข้อมูลนักเรียน'!C16 | T21: =IFERROR(SUMPRODUCT(((D21=D8)*(E21="Y")*(F21=F8)*(G21="Y")*(D21<>"")* (F21<>""))+((H21=H8)*(I21="Y")*(J21=J8)*(K21="Y")*(H21<>"")* (J21<>""))+((L21=L8)*(M21="Y")*(N21=N8)*(O21="Y")*(L21<>"")* (N21<>""))+((P21=P8)*(Q21="Y")*(R21=R8)*(S21="Y")*(P21<>"")* (R21<>""))),0) | U21: =IFERROR(SUMPRODUCT(((D21<>D8)*(E21="Y")*(F21<>F8)*(G21="Y")*(D21<>"")* (F21<>""))+((H21<>H8)*(I21="Y")*(J21<>J8)*(K21="Y")*(H21<>"")* (J21<>""))+((L21<>L8)*(M21="Y")*(N21<>N8)*(O21="Y")*(L21<>"")* (N21<>""))+((P21<>P8)*(Q21="Y")*(R21<>R8)*(S21="Y")*(P21<>"")* (R21<>""))),0) | V21: =IFERROR(SUMPRODUCT(((D21=D8)*(E21="Y")*(F21<>F8)*(G21="Y")*(D21<>"")* (F21<>""))+((H21=H8)*(I21="Y")*(J21<>J8)*(K21="Y")*(H21<>"")* (J21<>""))+((L21=L8)*(M21="Y")*(N21<>N8)*(O21="Y")*(L21<>"")* (N21<>""))+((P21=P8)*(Q21="Y")*(R21<>R8)*(S21="Y")*(P21<>"")* (R21<>""))),0) | W21: =IFERROR(SUMPRODUCT(((E21="N")*(D21<>"")* (F21<>""))+((I21="N")*(H21<>"")* (J21<>""))+((M21="N")*(L21<>"")* (N21<>""))+((Q21="N")*(P21<>"")* (R21<>""))),0) | X21: =IFERROR(U21/4,0)
B22: ='📥 ข้อมูลนักเรียน'!B17 | C22: ='📥 ข้อมูลนักเรียน'!C17 | T22: =IFERROR(SUMPRODUCT(((D22=D8)*(E22="Y")*(F22=F8)*(G22="Y")*(D22<>"")* (F22<>""))+((H22=H8)*(I22="Y")*(J22=J8)*(K22="Y")*(H22<>"")* (J22<>""))+((L22=L8)*(M22="Y")*(N22=N8)*(O22="Y")*(L22<>"")* (N22<>""))+((P22=P8)*(Q22="Y")*(R22=R8)*(S22="Y")*(P22<>"")* (R22<>""))),0) | U22: =IFERROR(SUMPRODUCT(((D22<>D8)*(E22="Y")*(F22<>F8)*(G22="Y")*(D22<>"")* (F22<>""))+((H22<>H8)*(I22="Y")*(J22<>J8)*(K22="Y")*(H22<>"")* (J22<>""))+((L22<>L8)*(M22="Y")*(N22<>N8)*(O22="Y")*(L22<>"")* (N22<>""))+((P22<>P8)*(Q22="Y")*(R22<>R8)*(S22="Y")*(P22<>"")* (R22<>""))),0) | V22: =IFERROR(SUMPRODUCT(((D22=D8)*(E22="Y")*(F22<>F8)*(G22="Y")*(D22<>"")* (F22<>""))+((H22=H8)*(I22="Y")*(J22<>J8)*(K22="Y")*(H22<>"")* (J22<>""))+((L22=L8)*(M22="Y")*(N22<>N8)*(O22="Y")*(L22<>"")* (N22<>""))+((P22=P8)*(Q22="Y")*(R22<>R8)*(S22="Y")*(P22<>"")* (R22<>""))),0) | W22: =IFERROR(SUMPRODUCT(((E22="N")*(D22<>"")* (F22<>""))+((I22="N")*(H22<>"")* (J22<>""))+((M22="N")*(L22<>"")* (N22<>""))+((Q22="N")*(P22<>"")* (R22<>""))),0) | X22: =IFERROR(U22/4,0)
B23: ='📥 ข้อมูลนักเรียน'!B18 | C23: ='📥 ข้อมูลนักเรียน'!C18 | T23: =IFERROR(SUMPRODUCT(((D23=D8)*(E23="Y")*(F23=F8)*(G23="Y")*(D23<>"")*(F23<>""))+((H23=H8)*(I23="Y")*(J23=J8)*(K23="Y")*(H23<>"")*(J23<>""))+((L23=L8)*(M23="Y")*(N23=N8)*(O23="Y")*(L23<>"")*(N23<>""))+((P23=P8)*(Q23="Y")*(R23=R8)*(S23="Y")*(P23<>"")*(R23<>""))),0) | U23: =IFERROR(SUMPRODUCT(((D23<>D8)*(E23="Y")*(F23<>F8)*(G23="Y")*(D23<>"")*(F23<>""))+((H23<>H8)*(I23="Y")*(J23<>J8)*(K23="Y")*(H23<>"")*(J23<>""))+((L23<>L8)*(M23="Y")*(N23<>N8)*(O23="Y")*(L23<>"")*(N23<>""))+((P23<>P8)*(Q23="Y")*(R23<>R8)*(S23="Y")*(P23<>"")*(R23<>""))),0) | V23: =IFERROR(SUMPRODUCT(((D23=D8)*(E23="Y")*(F23<>F8)*(G23="Y")*(D23<>"")*(F23<>""))+((H23=H8)*(I23="Y")*(J23<>J8)*(K23="Y")*(H23<>"")*(J23<>""))+((L23=L8)*(M23="Y")*(N23<>N8)*(O23="Y")*(L23<>"")*(N23<>""))+((P23=P8)*(Q23="Y")*(R23<>R8)*(S23="Y")*(P23<>"")*(R23<>""))),0) | W23: =IFERROR(SUMPRODUCT(((E23="N")*(D23<>"")*(F23<>""))+((I23="N")*(H23<>"")*(J23<>""))+((M23="N")*(L23<>"")*(N23<>""))+((Q23="N")*(P23<>"")*(R23<>""))),0) | X23: =IFERROR(U23/4,0)
B24: ='📥 ข้อมูลนักเรียน'!B19 | C24: ='📥 ข้อมูลนักเรียน'!C19 | T24: =IFERROR(SUMPRODUCT(((D24=D8)*(E24="Y")*(F24=F8)*(G24="Y")*(D24<>"")*(F24<>""))+((H24=H8)*(I24="Y")*(J24=J8)*(K24="Y")*(H24<>"")*(J24<>""))+((L24=L8)*(M24="Y")*(N24=N8)*(O24="Y")*(L24<>"")*(N24<>""))+((P24=P8)*(Q24="Y")*(R24=R8)*(S24="Y")*(P24<>"")*(R24<>""))),0) | U24: =IFERROR(SUMPRODUCT(((D24<>D8)*(E24="Y")*(F24<>F8)*(G24="Y")*(D24<>"")*(F24<>""))+((H24<>H8)*(I24="Y")*(J24<>J8)*(K24="Y")*(H24<>"")*(J24<>""))+((L24<>L8)*(M24="Y")*(N24<>N8)*(O24="Y")*(L24<>"")*(N24<>""))+((P24<>P8)*(Q24="Y")*(R24<>R8)*(S24="Y")*(P24<>"")*(R24<>""))),0) | V24: =IFERROR(SUMPRODUCT(((D24=D8)*(E24="Y")*(F24<>F8)*(G24="Y")*(D24<>"")*(F24<>""))+((H24=H8)*(I24="Y")*(J24<>J8)*(K24="Y")*(H24<>"")*(J24<>""))+((L24=L8)*(M24="Y")*(N24<>N8)*(O24="Y")*(L24<>"")*(N24<>""))+((P24=P8)*(Q24="Y")*(R24<>R8)*(S24="Y")*(P24<>"")*(R24<>""))),0) | W24: =IFERROR(SUMPRODUCT(((E24="N")*(D24<>"")*(F24<>""))+((I24="N")*(H24<>"")*(J24<>""))+((M24="N")*(L24<>"")*(N24<>""))+((Q24="N")*(P24<>"")*(R24<>""))),0) | X24: =IFERROR(U24/4,0)
B25: ='📥 ข้อมูลนักเรียน'!B20 | C25: ='📥 ข้อมูลนักเรียน'!C20 | T25: =IFERROR(SUMPRODUCT(((D25=D8)*(E25="Y")*(F25=F8)*(G25="Y")*(D25<>"")*(F25<>""))+((H25=H8)*(I25="Y")*(J25=J8)*(K25="Y")*(H25<>"")*(J25<>""))+((L25=L8)*(M25="Y")*(N25=N8)*(O25="Y")*(L25<>"")*(N25<>""))+((P25=P8)*(Q25="Y")*(R25=R8)*(S25="Y")*(P25<>"")*(R25<>""))),0) | U25: =IFERROR(SUMPRODUCT(((D25<>D8)*(E25="Y")*(F25<>F8)*(G25="Y")*(D25<>"")*(F25<>""))+((H25<>H8)*(I25="Y")*(J25<>J8)*(K25="Y")*(H25<>"")*(J25<>""))+((L25<>L8)*(M25="Y")*(N25<>N8)*(O25="Y")*(L25<>"")*(N25<>""))+((P25<>P8)*(Q25="Y")*(R25<>R8)*(S25="Y")*(P25<>"")*(R25<>""))),0) | V25: =IFERROR(SUMPRODUCT(((D25=D8)*(E25="Y")*(F25<>F8)*(G25="Y")*(D25<>"")*(F25<>""))+((H25=H8)*(I25="Y")*(J25<>J8)*(K25="Y")*(H25<>"")*(J25<>""))+((L25=L8)*(M25="Y")*(N25<>N8)*(O25="Y")*(L25<>"")*(N25<>""))+((P25=P8)*(Q25="Y")*(R25<>R8)*(S25="Y")*(P25<>"")*(R25<>""))),0) | W25: =IFERROR(SUMPRODUCT(((E25="N")*(D25<>"")*(F25<>""))+((I25="N")*(H25<>"")*(J25<>""))+((M25="N")*(L25<>"")*(N25<>""))+((Q25="N")*(P25<>"")*(R25<>""))),0) | X25: =IFERROR(U25/4,0)
B26: ='📥 ข้อมูลนักเรียน'!B21 | C26: ='📥 ข้อมูลนักเรียน'!C21 | T26: =IFERROR(SUMPRODUCT(((D26=D8)*(E26="Y")*(F26=F8)*(G26="Y")*(D26<>"")*(F26<>""))+((H26=H8)*(I26="Y")*(J26=J8)*(K26="Y")*(H26<>"")*(J26<>""))+((L26=L8)*(M26="Y")*(N26=N8)*(O26="Y")*(L26<>"")*(N26<>""))+((P26=P8)*(Q26="Y")*(R26=R8)*(S26="Y")*(P26<>"")*(R26<>""))),0) | U26: =IFERROR(SUMPRODUCT(((D26<>D8)*(E26="Y")*(F26<>F8)*(G26="Y")*(D26<>"")*(F26<>""))+((H26<>H8)*(I26="Y")*(J26<>J8)*(K26="Y")*(H26<>"")*(J26<>""))+((L26<>L8)*(M26="Y")*(N26<>N8)*(O26="Y")*(L26<>"")*(N26<>""))+((P26<>P8)*(Q26="Y")*(R26<>R8)*(S26="Y")*(P26<>"")*(R26<>""))),0) | V26: =IFERROR(SUMPRODUCT(((D26=D8)*(E26="Y")*(F26<>F8)*(G26="Y")*(D26<>"")*(F26<>""))+((H26=H8)*(I26="Y")*(J26<>J8)*(K26="Y")*(H26<>"")*(J26<>""))+((L26=L8)*(M26="Y")*(N26<>N8)*(O26="Y")*(L26<>"")*(N26<>""))+((P26=P8)*(Q26="Y")*(R26<>R8)*(S26="Y")*(P26<>"")*(R26<>""))),0) | W26: =IFERROR(SUMPRODUCT(((E26="N")*(D26<>"")*(F26<>""))+((I26="N")*(H26<>"")*(J26<>""))+((M26="N")*(L26<>"")*(N26<>""))+((Q26="N")*(P26<>"")*(R26<>""))),0) | X26: =IFERROR(U26/4,0)
B27: ='📥 ข้อมูลนักเรียน'!B22 | C27: ='📥 ข้อมูลนักเรียน'!C22 | T27: =IFERROR(SUMPRODUCT(((D27=D8)*(E27="Y")*(F27=F8)*(G27="Y")*(D27<>"")*(F27<>""))+((H27=H8)*(I27="Y")*(J27=J8)*(K27="Y")*(H27<>"")*(J27<>""))+((L27=L8)*(M27="Y")*(N27=N8)*(O27="Y")*(L27<>"")*(N27<>""))+((P27=P8)*(Q27="Y")*(R27=R8)*(S27="Y")*(P27<>"")*(R27<>""))),0) | U27: =IFERROR(SUMPRODUCT(((D27<>D8)*(E27="Y")*(F27<>F8)*(G27="Y")*(D27<>"")*(F27<>""))+((H27<>H8)*(I27="Y")*(J27<>J8)*(K27="Y")*(H27<>"")*(J27<>""))+((L27<>L8)*(M27="Y")*(N27<>N8)*(O27="Y")*(L27<>"")*(N27<>""))+((P27<>P8)*(Q27="Y")*(R27<>R8)*(S27="Y")*(P27<>"")*(R27<>""))),0) | V27: =IFERROR(SUMPRODUCT(((D27=D8)*(E27="Y")*(F27<>F8)*(G27="Y")*(D27<>"")*(F27<>""))+((H27=H8)*(I27="Y")*(J27<>J8)*(K27="Y")*(H27<>"")*(J27<>""))+((L27=L8)*(M27="Y")*(N27<>N8)*(O27="Y")*(L27<>"")*(N27<>""))+((P27=P8)*(Q27="Y")*(R27<>R8)*(S27="Y")*(P27<>"")*(R27<>""))),0) | W27: =IFERROR(SUMPRODUCT(((E27="N")*(D27<>"")*(F27<>""))+((I27="N")*(H27<>"")*(J27<>""))+((M27="N")*(L27<>"")*(N27<>""))+((Q27="N")*(P27<>"")*(R27<>""))),0) | X27: =IFERROR(U27/4,0)
B28: ='📥 ข้อมูลนักเรียน'!B23 | C28: ='📥 ข้อมูลนักเรียน'!C23 | T28: =IFERROR(SUMPRODUCT(((D28=D8)*(E28="Y")*(F28=F8)*(G28="Y")*(D28<>"")*(F28<>""))+((H28=H8)*(I28="Y")*(J28=J8)*(K28="Y")*(H28<>"")*(J28<>""))+((L28=L8)*(M28="Y")*(N28=N8)*(O28="Y")*(L28<>"")*(N28<>""))+((P28=P8)*(Q28="Y")*(R28=R8)*(S28="Y")*(P28<>"")*(R28<>""))),0) | U28: =IFERROR(SUMPRODUCT(((D28<>D8)*(E28="Y")*(F28<>F8)*(G28="Y")*(D28<>"")*(F28<>""))+((H28<>H8)*(I28="Y")*(J28<>J8)*(K28="Y")*(H28<>"")*(J28<>""))+((L28<>L8)*(M28="Y")*(N28<>N8)*(O28="Y")*(L28<>"")*(N28<>""))+((P28<>P8)*(Q28="Y")*(R28<>R8)*(S28="Y")*(P28<>"")*(R28<>""))),0) | V28: =IFERROR(SUMPRODUCT(((D28=D8)*(E28="Y")*(F28<>F8)*(G28="Y")*(D28<>"")*(F28<>""))+((H28=H8)*(I28="Y")*(J28<>J8)*(K28="Y")*(H28<>"")*(J28<>""))+((L28=L8)*(M28="Y")*(N28<>N8)*(O28="Y")*(L28<>"")*(N28<>""))+((P28=P8)*(Q28="Y")*(R28<>R8)*(S28="Y")*(P28<>"")*(R28<>""))),0) | W28: =IFERROR(SUMPRODUCT(((E28="N")*(D28<>"")*(F28<>""))+((I28="N")*(H28<>"")*(J28<>""))+((M28="N")*(L28<>"")*(N28<>""))+((Q28="N")*(P28<>"")*(R28<>""))),0) | X28: =IFERROR(U28/4,0)
B29: ='📥 ข้อมูลนักเรียน'!B24 | C29: ='📥 ข้อมูลนักเรียน'!C24 | T29: =IFERROR(SUMPRODUCT(((D29=D8)*(E29="Y")*(F29=F8)*(G29="Y")*(D29<>"")*(F29<>""))+((H29=H8)*(I29="Y")*(J29=J8)*(K29="Y")*(H29<>"")*(J29<>""))+((L29=L8)*(M29="Y")*(N29=N8)*(O29="Y")*(L29<>"")*(N29<>""))+((P29=P8)*(Q29="Y")*(R29=R8)*(S29="Y")*(P29<>"")*(R29<>""))),0) | U29: =IFERROR(SUMPRODUCT(((D29<>D8)*(E29="Y")*(F29<>F8)*(G29="Y")*(D29<>"")*(F29<>""))+((H29<>H8)*(I29="Y")*(J29<>J8)*(K29="Y")*(H29<>"")*(J29<>""))+((L29<>L8)*(M29="Y")*(N29<>N8)*(O29="Y")*(L29<>"")*(N29<>""))+((P29<>P8)*(Q29="Y")*(R29<>R8)*(S29="Y")*(P29<>"")*(R29<>""))),0) | V29: =IFERROR(SUMPRODUCT(((D29=D8)*(E29="Y")*(F29<>F8)*(G29="Y")*(D29<>"")*(F29<>""))+((H29=H8)*(I29="Y")*(J29<>J8)*(K29="Y")*(H29<>"")*(J29<>""))+((L29=L8)*(M29="Y")*(N29<>N8)*(O29="Y")*(L29<>"")*(N29<>""))+((P29=P8)*(Q29="Y")*(R29<>R8)*(S29="Y")*(P29<>"")*(R29<>""))),0) | W29: =IFERROR(SUMPRODUCT(((E29="N")*(D29<>"")*(F29<>""))+((I29="N")*(H29<>"")*(J29<>""))+((M29="N")*(L29<>"")*(N29<>""))+((Q29="N")*(P29<>"")*(R29<>""))),0) | X29: =IFERROR(U29/4,0)
B30: ='📥 ข้อมูลนักเรียน'!B25 | C30: ='📥 ข้อมูลนักเรียน'!C25 | T30: =IFERROR(SUMPRODUCT(((D30=D8)*(E30="Y")*(F30=F8)*(G30="Y")*(D30<>"")*(F30<>""))+((H30=H8)*(I30="Y")*(J30=J8)*(K30="Y")*(H30<>"")*(J30<>""))+((L30=L8)*(M30="Y")*(N30=N8)*(O30="Y")*(L30<>"")*(N30<>""))+((P30=P8)*(Q30="Y")*(R30=R8)*(S30="Y")*(P30<>"")*(R30<>""))),0) | U30: =IFERROR(SUMPRODUCT(((D30<>D8)*(E30="Y")*(F30<>F8)*(G30="Y")*(D30<>"")*(F30<>""))+((H30<>H8)*(I30="Y")*(J30<>J8)*(K30="Y")*(H30<>"")*(J30<>""))+((L30<>L8)*(M30="Y")*(N30<>N8)*(O30="Y")*(L30<>"")*(N30<>""))+((P30<>P8)*(Q30="Y")*(R30<>R8)*(S30="Y")*(P30<>"")*(R30<>""))),0) | V30: =IFERROR(SUMPRODUCT(((D30=D8)*(E30="Y")*(F30<>F8)*(G30="Y")*(D30<>"")*(F30<>""))+((H30=H8)*(I30="Y")*(J30<>J8)*(K30="Y")*(H30<>"")*(J30<>""))+((L30=L8)*(M30="Y")*(N30<>N8)*(O30="Y")*(L30<>"")*(N30<>""))+((P30=P8)*(Q30="Y")*(R30<>R8)*(S30="Y")*(P30<>"")*(R30<>""))),0) | W30: =IFERROR(SUMPRODUCT(((E30="N")*(D30<>"")*(F30<>""))+((I30="N")*(H30<>"")*(J30<>""))+((M30="N")*(L30<>"")*(N30<>""))+((Q30="N")*(P30<>"")*(R30<>""))),0) | X30: =IFERROR(U30/4,0)
B31: ='📥 ข้อมูลนักเรียน'!B26 | C31: ='📥 ข้อมูลนักเรียน'!C26 | T31: =IFERROR(SUMPRODUCT(((D31=D8)*(E31="Y")*(F31=F8)*(G31="Y")*(D31<>"")*(F31<>""))+((H31=H8)*(I31="Y")*(J31=J8)*(K31="Y")*(H31<>"")*(J31<>""))+((L31=L8)*(M31="Y")*(N31=N8)*(O31="Y")*(L31<>"")*(N31<>""))+((P31=P8)*(Q31="Y")*(R31=R8)*(S31="Y")*(P31<>"")*(R31<>""))),0) | U31: =IFERROR(SUMPRODUCT(((D31<>D8)*(E31="Y")*(F31<>F8)*(G31="Y")*(D31<>"")*(F31<>""))+((H31<>H8)*(I31="Y")*(J31<>J8)*(K31="Y")*(H31<>"")*(J31<>""))+((L31<>L8)*(M31="Y")*(N31<>N8)*(O31="Y")*(L31<>"")*(N31<>""))+((P31<>P8)*(Q31="Y")*(R31<>R8)*(S31="Y")*(P31<>"")*(R31<>""))),0) | V31: =IFERROR(SUMPRODUCT(((D31=D8)*(E31="Y")*(F31<>F8)*(G31="Y")*(D31<>"")*(F31<>""))+((H31=H8)*(I31="Y")*(J31<>J8)*(K31="Y")*(H31<>"")*(J31<>""))+((L31=L8)*(M31="Y")*(N31<>N8)*(O31="Y")*(L31<>"")*(N31<>""))+((P31=P8)*(Q31="Y")*(R31<>R8)*(S31="Y")*(P31<>"")*(R31<>""))),0) | W31: =IFERROR(SUMPRODUCT(((E31="N")*(D31<>"")*(F31<>""))+((I31="N")*(H31<>"")*(J31<>""))+((M31="N")*(L31<>"")*(N31<>""))+((Q31="N")*(P31<>"")*(R31<>""))),0) | X31: =IFERROR(U31/4,0)
B32: ='📥 ข้อมูลนักเรียน'!B27 | C32: ='📥 ข้อมูลนักเรียน'!C27 | T32: =IFERROR(SUMPRODUCT(((D32=D8)*(E32="Y")*(F32=F8)*(G32="Y")*(D32<>"")*(F32<>""))+((H32=H8)*(I32="Y")*(J32=J8)*(K32="Y")*(H32<>"")*(J32<>""))+((L32=L8)*(M32="Y")*(N32=N8)*(O32="Y")*(L32<>"")*(N32<>""))+((P32=P8)*(Q32="Y")*(R32=R8)*(S32="Y")*(P32<>"")*(R32<>""))),0) | U32: =IFERROR(SUMPRODUCT(((D32<>D8)*(E32="Y")*(F32<>F8)*(G32="Y")*(D32<>"")*(F32<>""))+((H32<>H8)*(I32="Y")*(J32<>J8)*(K32="Y")*(H32<>"")*(J32<>""))+((L32<>L8)*(M32="Y")*(N32<>N8)*(O32="Y")*(L32<>"")*(N32<>""))+((P32<>P8)*(Q32="Y")*(R32<>R8)*(S32="Y")*(P32<>"")*(R32<>""))),0) | V32: =IFERROR(SUMPRODUCT(((D32=D8)*(E32="Y")*(F32<>F8)*(G32="Y")*(D32<>"")*(F32<>""))+((H32=H8)*(I32="Y")*(J32<>J8)*(K32="Y")*(H32<>"")*(J32<>""))+((L32=L8)*(M32="Y")*(N32<>N8)*(O32="Y")*(L32<>"")*(N32<>""))+((P32=P8)*(Q32="Y")*(R32<>R8)*(S32="Y")*(P32<>"")*(R32<>""))),0) | W32: =IFERROR(SUMPRODUCT(((E32="N")*(D32<>"")*(F32<>""))+((I32="N")*(H32<>"")*(J32<>""))+((M32="N")*(L32<>"")*(N32<>""))+((Q32="N")*(P32<>"")*(R32<>""))),0) | X32: =IFERROR(U32/4,0)
B33: ='📥 ข้อมูลนักเรียน'!B28 | C33: ='📥 ข้อมูลนักเรียน'!C28 | T33: =IFERROR(SUMPRODUCT(((D33=D8)*(E33="Y")*(F33=F8)*(G33="Y")*(D33<>"")*(F33<>""))+((H33=H8)*(I33="Y")*(J33=J8)*(K33="Y")*(H33<>"")*(J33<>""))+((L33=L8)*(M33="Y")*(N33=N8)*(O33="Y")*(L33<>"")*(N33<>""))+((P33=P8)*(Q33="Y")*(R33=R8)*(S33="Y")*(P33<>"")*(R33<>""))),0) | U33: =IFERROR(SUMPRODUCT(((D33<>D8)*(E33="Y")*(F33<>F8)*(G33="Y")*(D33<>"")*(F33<>""))+((H33<>H8)*(I33="Y")*(J33<>J8)*(K33="Y")*(H33<>"")*(J33<>""))+((L33<>L8)*(M33="Y")*(N33<>N8)*(O33="Y")*(L33<>"")*(N33<>""))+((P33<>P8)*(Q33="Y")*(R33<>R8)*(S33="Y")*(P33<>"")*(R33<>""))),0) | V33: =IFERROR(SUMPRODUCT(((D33=D8)*(E33="Y")*(F33<>F8)*(G33="Y")*(D33<>"")*(F33<>""))+((H33=H8)*(I33="Y")*(J33<>J8)*(K33="Y")*(H33<>"")*(J33<>""))+((L33=L8)*(M33="Y")*(N33<>N8)*(O33="Y")*(L33<>"")*(N33<>""))+((P33=P8)*(Q33="Y")*(R33<>R8)*(S33="Y")*(P33<>"")*(R33<>""))),0) | W33: =IFERROR(SUMPRODUCT(((E33="N")*(D33<>"")*(F33<>""))+((I33="N")*(H33<>"")*(J33<>""))+((M33="N")*(L33<>"")*(N33<>""))+((Q33="N")*(P33<>"")*(R33<>""))),0) | X33: =IFERROR(U33/4,0)
B34: ='📥 ข้อมูลนักเรียน'!B29 | C34: ='📥 ข้อมูลนักเรียน'!C29 | T34: =IFERROR(SUMPRODUCT(((D34=D8)*(E34="Y")*(F34=F8)*(G34="Y")*(D34<>"")*(F34<>""))+((H34=H8)*(I34="Y")*(J34=J8)*(K34="Y")*(H34<>"")*(J34<>""))+((L34=L8)*(M34="Y")*(N34=N8)*(O34="Y")*(L34<>"")*(N34<>""))+((P34=P8)*(Q34="Y")*(R34=R8)*(S34="Y")*(P34<>"")*(R34<>""))),0) | U34: =IFERROR(SUMPRODUCT(((D34<>D8)*(E34="Y")*(F34<>F8)*(G34="Y")*(D34<>"")*(F34<>""))+((H34<>H8)*(I34="Y")*(J34<>J8)*(K34="Y")*(H34<>"")*(J34<>""))+((L34<>L8)*(M34="Y")*(N34<>N8)*(O34="Y")*(L34<>"")*(N34<>""))+((P34<>P8)*(Q34="Y")*(R34<>R8)*(S34="Y")*(P34<>"")*(R34<>""))),0) | V34: =IFERROR(SUMPRODUCT(((D34=D8)*(E34="Y")*(F34<>F8)*(G34="Y")*(D34<>"")*(F34<>""))+((H34=H8)*(I34="Y")*(J34<>J8)*(K34="Y")*(H34<>"")*(J34<>""))+((L34=L8)*(M34="Y")*(N34<>N8)*(O34="Y")*(L34<>"")*(N34<>""))+((P34=P8)*(Q34="Y")*(R34<>R8)*(S34="Y")*(P34<>"")*(R34<>""))),0) | W34: =IFERROR(SUMPRODUCT(((E34="N")*(D34<>"")*(F34<>""))+((I34="N")*(H34<>"")*(J34<>""))+((M34="N")*(L34<>"")*(N34<>""))+((Q34="N")*(P34<>"")*(R34<>""))),0) | X34: =IFERROR(U34/4,0)
B35: ='📥 ข้อมูลนักเรียน'!B30 | C35: ='📥 ข้อมูลนักเรียน'!C30 | T35: =IFERROR(SUMPRODUCT(((D35=D8)*(E35="Y")*(F35=F8)*(G35="Y")*(D35<>"")*(F35<>""))+((H35=H8)*(I35="Y")*(J35=J8)*(K35="Y")*(H35<>"")*(J35<>""))+((L35=L8)*(M35="Y")*(N35=N8)*(O35="Y")*(L35<>"")*(N35<>""))+((P35=P8)*(Q35="Y")*(R35=R8)*(S35="Y")*(P35<>"")*(R35<>""))),0) | U35: =IFERROR(SUMPRODUCT(((D35<>D8)*(E35="Y")*(F35<>F8)*(G35="Y")*(D35<>"")*(F35<>""))+((H35<>H8)*(I35="Y")*(J35<>J8)*(K35="Y")*(H35<>"")*(J35<>""))+((L35<>L8)*(M35="Y")*(N35<>N8)*(O35="Y")*(L35<>"")*(N35<>""))+((P35<>P8)*(Q35="Y")*(R35<>R8)*(S35="Y")*(P35<>"")*(R35<>""))),0) | V35: =IFERROR(SUMPRODUCT(((D35=D8)*(E35="Y")*(F35<>F8)*(G35="Y")*(D35<>"")*(F35<>""))+((H35=H8)*(I35="Y")*(J35<>J8)*(K35="Y")*(H35<>"")*(J35<>""))+((L35=L8)*(M35="Y")*(N35<>N8)*(O35="Y")*(L35<>"")*(N35<>""))+((P35=P8)*(Q35="Y")*(R35<>R8)*(S35="Y")*(P35<>"")*(R35<>""))),0) | W35: =IFERROR(SUMPRODUCT(((E35="N")*(D35<>"")*(F35<>""))+((I35="N")*(H35<>"")*(J35<>""))+((M35="N")*(L35<>"")*(N35<>""))+((Q35="N")*(P35<>"")*(R35<>""))),0) | X35: =IFERROR(U35/4,0)
B36: ='📥 ข้อมูลนักเรียน'!B31 | C36: ='📥 ข้อมูลนักเรียน'!C31 | T36: =IFERROR(SUMPRODUCT(((D36=D8)*(E36="Y")*(F36=F8)*(G36="Y")*(D36<>"")*(F36<>""))+((H36=H8)*(I36="Y")*(J36=J8)*(K36="Y")*(H36<>"")*(J36<>""))+((L36=L8)*(M36="Y")*(N36=N8)*(O36="Y")*(L36<>"")*(N36<>""))+((P36=P8)*(Q36="Y")*(R36=R8)*(S36="Y")*(P36<>"")*(R36<>""))),0) | U36: =IFERROR(SUMPRODUCT(((D36<>D8)*(E36="Y")*(F36<>F8)*(G36="Y")*(D36<>"")*(F36<>""))+((H36<>H8)*(I36="Y")*(J36<>J8)*(K36="Y")*(H36<>"")*(J36<>""))+((L36<>L8)*(M36="Y")*(N36<>N8)*(O36="Y")*(L36<>"")*(N36<>""))+((P36<>P8)*(Q36="Y")*(R36<>R8)*(S36="Y")*(P36<>"")*(R36<>""))),0) | V36: =IFERROR(SUMPRODUCT(((D36=D8)*(E36="Y")*(F36<>F8)*(G36="Y")*(D36<>"")*(F36<>""))+((H36=H8)*(I36="Y")*(J36<>J8)*(K36="Y")*(H36<>"")*(J36<>""))+((L36=L8)*(M36="Y")*(N36<>N8)*(O36="Y")*(L36<>"")*(N36<>""))+((P36=P8)*(Q36="Y")*(R36<>R8)*(S36="Y")*(P36<>"")*(R36<>""))),0) | W36: =IFERROR(SUMPRODUCT(((E36="N")*(D36<>"")*(F36<>""))+((I36="N")*(H36<>"")*(J36<>""))+((M36="N")*(L36<>"")*(N36<>""))+((Q36="N")*(P36<>"")*(R36<>""))),0) | X36: =IFERROR(U36/4,0)
B37: ='📥 ข้อมูลนักเรียน'!B32 | C37: ='📥 ข้อมูลนักเรียน'!C32 | T37: =IFERROR(SUMPRODUCT(((D37=D8)*(E37="Y")*(F37=F8)*(G37="Y")*(D37<>"")*(F37<>""))+((H37=H8)*(I37="Y")*(J37=J8)*(K37="Y")*(H37<>"")*(J37<>""))+((L37=L8)*(M37="Y")*(N37=N8)*(O37="Y")*(L37<>"")*(N37<>""))+((P37=P8)*(Q37="Y")*(R37=R8)*(S37="Y")*(P37<>"")*(R37<>""))),0) | U37: =IFERROR(SUMPRODUCT(((D37<>D8)*(E37="Y")*(F37<>F8)*(G37="Y")*(D37<>"")*(F37<>""))+((H37<>H8)*(I37="Y")*(J37<>J8)*(K37="Y")*(H37<>"")*(J37<>""))+((L37<>L8)*(M37="Y")*(N37<>N8)*(O37="Y")*(L37<>"")*(N37<>""))+((P37<>P8)*(Q37="Y")*(R37<>R8)*(S37="Y")*(P37<>"")*(R37<>""))),0) | V37: =IFERROR(SUMPRODUCT(((D37=D8)*(E37="Y")*(F37<>F8)*(G37="Y")*(D37<>"")*(F37<>""))+((H37=H8)*(I37="Y")*(J37<>J8)*(K37="Y")*(H37<>"")*(J37<>""))+((L37=L8)*(M37="Y")*(N37<>N8)*(O37="Y")*(L37<>"")*(N37<>""))+((P37=P8)*(Q37="Y")*(R37<>R8)*(S37="Y")*(P37<>"")*(R37<>""))),0) | W37: =IFERROR(SUMPRODUCT(((E37="N")*(D37<>"")*(F37<>""))+((I37="N")*(H37<>"")*(J37<>""))+((M37="N")*(L37<>"")*(N37<>""))+((Q37="N")*(P37<>"")*(R37<>""))),0) | X37: =IFERROR(U37/4,0)
B38: ='📥 ข้อมูลนักเรียน'!B33 | C38: ='📥 ข้อมูลนักเรียน'!C33 | T38: =IFERROR(SUMPRODUCT(((D38=D8)*(E38="Y")*(F38=F8)*(G38="Y")*(D38<>"")*(F38<>""))+((H38=H8)*(I38="Y")*(J38=J8)*(K38="Y")*(H38<>"")*(J38<>""))+((L38=L8)*(M38="Y")*(N38=N8)*(O38="Y")*(L38<>"")*(N38<>""))+((P38=P8)*(Q38="Y")*(R38=R8)*(S38="Y")*(P38<>"")*(R38<>""))),0) | U38: =IFERROR(SUMPRODUCT(((D38<>D8)*(E38="Y")*(F38<>F8)*(G38="Y")*(D38<>"")*(F38<>""))+((H38<>H8)*(I38="Y")*(J38<>J8)*(K38="Y")*(H38<>"")*(J38<>""))+((L38<>L8)*(M38="Y")*(N38<>N8)*(O38="Y")*(L38<>"")*(N38<>""))+((P38<>P8)*(Q38="Y")*(R38<>R8)*(S38="Y")*(P38<>"")*(R38<>""))),0) | V38: =IFERROR(SUMPRODUCT(((D38=D8)*(E38="Y")*(F38<>F8)*(G38="Y")*(D38<>"")*(F38<>""))+((H38=H8)*(I38="Y")*(J38<>J8)*(K38="Y")*(H38<>"")*(J38<>""))+((L38=L8)*(M38="Y")*(N38<>N8)*(O38="Y")*(L38<>"")*(N38<>""))+((P38=P8)*(Q38="Y")*(R38<>R8)*(S38="Y")*(P38<>"")*(R38<>""))),0) | W38: =IFERROR(SUMPRODUCT(((E38="N")*(D38<>"")*(F38<>""))+((I38="N")*(H38<>"")*(J38<>""))+((M38="N")*(L38<>"")*(N38<>""))+((Q38="N")*(P38<>"")*(R38<>""))),0) | X38: =IFERROR(U38/4,0)
B39: ='📥 ข้อมูลนักเรียน'!B34 | C39: ='📥 ข้อมูลนักเรียน'!C34 | T39: =IFERROR(SUMPRODUCT(((D39=D8)*(E39="Y")*(F39=F8)*(G39="Y")*(D39<>"")*(F39<>""))+((H39=H8)*(I39="Y")*(J39=J8)*(K39="Y")*(H39<>"")*(J39<>""))+((L39=L8)*(M39="Y")*(N39=N8)*(O39="Y")*(L39<>"")*(N39<>""))+((P39=P8)*(Q39="Y")*(R39=R8)*(S39="Y")*(P39<>"")*(R39<>""))),0) | U39: =IFERROR(SUMPRODUCT(((D39<>D8)*(E39="Y")*(F39<>F8)*(G39="Y")*(D39<>"")*(F39<>""))+((H39<>H8)*(I39="Y")*(J39<>J8)*(K39="Y")*(H39<>"")*(J39<>""))+((L39<>L8)*(M39="Y")*(N39<>N8)*(O39="Y")*(L39<>"")*(N39<>""))+((P39<>P8)*(Q39="Y")*(R39<>R8)*(S39="Y")*(P39<>"")*(R39<>""))),0) | V39: =IFERROR(SUMPRODUCT(((D39=D8)*(E39="Y")*(F39<>F8)*(G39="Y")*(D39<>"")*(F39<>""))+((H39=H8)*(I39="Y")*(J39<>J8)*(K39="Y")*(H39<>"")*(J39<>""))+((L39=L8)*(M39="Y")*(N39<>N8)*(O39="Y")*(L39<>"")*(N39<>""))+((P39=P8)*(Q39="Y")*(R39<>R8)*(S39="Y")*(P39<>"")*(R39<>""))),0) | W39: =IFERROR(SUMPRODUCT(((E39="N")*(D39<>"")*(F39<>""))+((I39="N")*(H39<>"")*(J39<>""))+((M39="N")*(L39<>"")*(N39<>""))+((Q39="N")*(P39<>"")*(R39<>""))),0) | X39: =IFERROR(U39/4,0)
B40: ='📥 ข้อมูลนักเรียน'!B35 | C40: ='📥 ข้อมูลนักเรียน'!C35 | T40: =IFERROR(SUMPRODUCT(((D40=D8)*(E40="Y")*(F40=F8)*(G40="Y")*(D40<>"")*(F40<>""))+((H40=H8)*(I40="Y")*(J40=J8)*(K40="Y")*(H40<>"")*(J40<>""))+((L40=L8)*(M40="Y")*(N40=N8)*(O40="Y")*(L40<>"")*(N40<>""))+((P40=P8)*(Q40="Y")*(R40=R8)*(S40="Y")*(P40<>"")*(R40<>""))),0) | U40: =IFERROR(SUMPRODUCT(((D40<>D8)*(E40="Y")*(F40<>F8)*(G40="Y")*(D40<>"")*(F40<>""))+((H40<>H8)*(I40="Y")*(J40<>J8)*(K40="Y")*(H40<>"")*(J40<>""))+((L40<>L8)*(M40="Y")*(N40<>N8)*(O40="Y")*(L40<>"")*(N40<>""))+((P40<>P8)*(Q40="Y")*(R40<>R8)*(S40="Y")*(P40<>"")*(R40<>""))),0) | V40: =IFERROR(SUMPRODUCT(((D40=D8)*(E40="Y")*(F40<>F8)*(G40="Y")*(D40<>"")*(F40<>""))+((H40=H8)*(I40="Y")*(J40<>J8)*(K40="Y")*(H40<>"")*(J40<>""))+((L40=L8)*(M40="Y")*(N40<>N8)*(O40="Y")*(L40<>"")*(N40<>""))+((P40=P8)*(Q40="Y")*(R40<>R8)*(S40="Y")*(P40<>"")*(R40<>""))),0) | W40: =IFERROR(SUMPRODUCT(((E40="N")*(D40<>"")*(F40<>""))+((I40="N")*(H40<>"")*(J40<>""))+((M40="N")*(L40<>"")*(N40<>""))+((Q40="N")*(P40<>"")*(R40<>""))),0) | X40: =IFERROR(U40/4,0)
...

Sheet 📝 Four-tier กรอก
B1: 📝 กรอกคำตอบ Four-tier | T1,T3: ก/ข/ค/ง | T2,T4: Y=มั่นใจ / N=ไม่มั่นใจ
B2: เฉลย (T1 & T3)
B3: 🔵 Pre-test — กรอกคำตอบ Tier 1–4 ของนักเรียนแต่ละคน
B4: ที่ | C4: ชื่อนักเรียน | D4: ข้อ 1 | H4: ข้อ 2 | L4: ข้อ 3 | P4: ข้อ 4 | T4: ข้อ 5 | X4: ข้อ 6 | AB4: ข้อ 7 | AF4: ข้อ 8 | AJ4: ข้อ 9 | AN4: ข้อ 10 | AR4: ข้อ 11 | AV4: ข้อ 12 | AZ4: ข้อ 13 | BD4: ข้อ 14 | BH4: ข้อ 15 | BL4: ข้อ 16 | BP4: ข้อ 17 | BT4: ข้อ 18 | BX4: ข้อ 19 | CB4: ข้อ 20
B5: ที่ | C5: ชื่อนักเรียน | D5: T1 คำตอบ | E5: T2 มั่นใจ | F5: T3 เหตุผล | G5: T4 มั่นใจ | H5: T1 คำตอบ | I5: T2 มั่นใจ | J5: T3 เหตุผล | K5: T4 มั่นใจ | L5: T1 คำตอบ | M5: T2 มั่นใจ | N5: T3 เหตุผล | O5: T4 มั่นใจ | P5: T1 คำตอบ | Q5: T2 มั่นใจ | R5: T3 เหตุผล | S5: T4 มั่นใจ | T5: T1 คำตอบ | U5: T2 มั่นใจ | V5: T3 เหตุผล | W5: T4 มั่นใจ | X5: T1 คำตอบ | Y5: T2 มั่นใจ | Z5: T3 เหตุผล | AA5: T4 มั่นใจ | AB5: T1 คำตอบ | AC5: T2 มั่นใจ | AD5: T3 เหตุผล | AE5: T4 มั่นใจ | AF5: T1 คำตอบ | AG5: T2 มั่นใจ | AH5: T3 เหตุผล | AI5: T4 มั่นใจ | AJ5: T1 คำตอบ | AK5: T2 มั่นใจ | AL5: T3 เหตุผล | AM5: T4 มั่นใจ | AN5: T1 คำตอบ | AO5: T2 มั่นใจ | AP5: T3 เหตุผล | AQ5: T4 มั่นใจ | AR5: T1 คำตอบ | AS5: T2 มั่นใจ | AT5: T3 เหตุผล | AU5: T4 มั่นใจ | AV5: T1 คำตอบ | AW5: T2 มั่นใจ | AX5: T3 เหตุผล | AY5: T4 มั่นใจ | AZ5: T1 คำตอบ | BA5: T2 มั่นใจ | BB5: T3 เหตุผล | BC5: T4 มั่นใจ | BD5: T1 คำตอบ | BE5: T2 มั่นใจ | BF5: T3 เหตุผล | BG5: T4 มั่นใจ | BH5: T1 คำตอบ | BI5: T2 มั่นใจ | BJ5: T3 เหตุผล | BK5: T4 มั่นใจ | BL5: T1 คำตอบ | BM5: T2 มั่นใจ | BN5: T3 เหตุผล | BO5: T4 มั่นใจ | BP5: T1 คำตอบ | BQ5: T2 มั่นใจ | BR5: T3 เหตุผล | BS5: T4 มั่นใจ | BT5: T1 คำตอบ | BU5: T2 มั่นใจ | BV5: T3 เหตุผล | BW5: T4 มั่นใจ | BX5: T1 คำตอบ | BY5: T2 มั่นใจ | BZ5: T3 เหตุผล | CA5: T4 มั่นใจ | CB5: T1 คำตอบ | CC5: T2 มั่นใจ | CD5: T3 เหตุผล | CE5: T4 มั่นใจ
B6: KEY | C6: ← กรอกเฉลยที่ถูกต้อง (T1 & T3) | D6: ข | E6: - | F6: 3 | G6: - | H6: ก | I6: - | J6: 4 | K6: - | L6: ค | M6: - | N6: 1 | O6: - | P6: ง | Q6: - | R6: 2 | S6: - | T6: ข | U6: - | V6: 4 | W6: - | X6: ค | Y6: - | Z6: 2 | AA6: - | AB6: ก | AC6: - | AD6: 3 | AE6: - | AF6: ง | AG6: - | AH6: 1 | AI6: - | AJ6: ข | AK6: - | AL6: 1 | AM6: - | AN6: ก | AO6: - | AP6: 3 | AQ6: - | AR6: ค | AS6: - | AT6: 4 | AU6: - | AV6: ง | AW6: - | AX6: 2 | AY6: - | AZ6: ข | BA6: - | BB6: 3 | BC6: - | BD6: ค | BE6: - | BF6: 1 | BG6: - | BH6: ก | BI6: - | BJ6: 4 | BK6: - | BL6: ง | BM6: - | BN6: 2 | BO6: - | BP6: ข | BQ6: - | BR6: 4 | BS6: - | BT6: ค | BU6: - | BV6: 2 | BW6: - | BX6: ก | BY6: - | BZ6: 3 | CA6: - | CB6: ง | CC6: - | CD6: 1 | CE6: -
B7: ='📥 ข้อมูลนักเรียน'!B4 | C7: ='📥 ข้อมูลนักเรียน'!C4
B8: ='📥 ข้อมูลนักเรียน'!B5 | C8: ='📥 ข้อมูลนักเรียน'!C5
B9: ='📥 ข้อมูลนักเรียน'!B6 | C9: ='📥 ข้อมูลนักเรียน'!C6
B10: ='📥 ข้อมูลนักเรียน'!B7 | C10: ='📥 ข้อมูลนักเรียน'!C7
B11: ='📥 ข้อมูลนักเรียน'!B8 | C11: ='📥 ข้อมูลนักเรียน'!C8
B12: ='📥 ข้อมูลนักเรียน'!B9 | C12: ='📥 ข้อมูลนักเรียน'!C9
B13: ='📥 ข้อมูลนักเรียน'!B10 | C13: ='📥 ข้อมูลนักเรียน'!C10
B14: ='📥 ข้อมูลนักเรียน'!B11 | C14: ='📥 ข้อมูลนักเรียน'!C11
B15: ='📥 ข้อมูลนักเรียน'!B12 | C15: ='📥 ข้อมูลนักเรียน'!C12
B16: ='📥 ข้อมูลนักเรียน'!B13 | C16: ='📥 ข้อมูลนักเรียน'!C13
B17: ='📥 ข้อมูลนักเรียน'!B14 | C17: ='📥 ข้อมูลนักเรียน'!C14
B18: ='📥 ข้อมูลนักเรียน'!B15 | C18: ='📥 ข้อมูลนักเรียน'!C15
... B46: ='📥 ข้อมูลนักเรียน'!B43 | C46: ='📥 ข้อมูลนักเรียน'!C43
B48: 🟢 Post-test — กรอกคำตอบ Tier 1–4 ของนักเรียนแต่ละคน
B49: ที่ | C49: ชื่อนักเรียน | D49: ข้อ 1 | H49: ข้อ 2 | L49: ข้อ 3 | P49: ข้อ 4 | T49: ข้อ 5 | X49: ข้อ 6 | AB49: ข้อ 7 | AF49: ข้อ 8 | AJ49: ข้อ 9 | AN49: ข้อ 10 | AR49: ข้อ 11 | AV49: ข้อ 12 | AZ49: ข้อ 13 | BD49: ข้อ 14 | BH49: ข้อ 15 | BL49: ข้อ 16 | BP49: ข้อ 17 | BT49: ข้อ 18 | BX49: ข้อ 19 | CB49: ข้อ 20
B50: ที่ | C50: ชื่อนักเรียน | D50: T1 คำตอบ | E50: T2 มั่นใจ | F50: T3 เหตุผล | G50: T4 มั่นใจ | H50: T1 คำตอบ | I50: T2 มั่นใจ | J50: T3 เหตุผล | K50: T4 มั่นใจ | L50: T1 คำตอบ | M50: T2 มั่นใจ | N50: T3 เหตุผล | O50: T4 มั่นใจ | P50: T1 คำตอบ | Q50: T2 มั่นใจ | R50: T3 เหตุผล | S50: T4 มั่นใจ | T50: T1 คำตอบ | U50: T2 มั่นใจ | V50: T3 เหตุผล | W50: T4 มั่นใจ | X50: T1 คำตอบ | Y50: T2 มั่นใจ | Z50: T3 เหตุผล | AA50: T4 มั่นใจ | AB50: T1 คำตอบ | AC50: T2 มั่นใจ | AD50: T3 เหตุผล | AE50: T4 มั่นใจ | AF50: T1 คำตอบ | AG50: T2 มั่นใจ | AH50: T3 เหตุผล | AI50: T4 มั่นใจ | AJ50: T1 คำตอบ | AK50: T2 มั่นใจ | AL50: T3 เหตุผล | AM50: T4 มั่นใจ | AN50: T1 คำตอบ | AO50: T2 มั่นใจ | AP50: T3 เหตุผล | AQ50: T4 มั่นใจ | AR50: T1 คำตอบ | AS50: T2 มั่นใจ | AT50: T3 เหตุผล | AU50: T4 มั่นใจ | AV50: T1 คำตอบ | AW50: T2 มั่นใจ | AX50: T3 เหตุผล | AY50: T4 มั่นใจ | AZ50: T1 คำตอบ | BA50: T2 มั่นใจ | BB50: T3 เหตุผล | BC50: T4 มั่นใจ | BD50: T1 คำตอบ | BE50: T2 มั่นใจ | BF50: T3 เหตุผล | BG50: T4 มั่นใจ | BH50: T1 คำตอบ | BI50: T2 มั่นใจ | BJ50: T3 เหตุผล | BK50: T4 มั่นใจ | BL50: T1 คำตอบ | BM50: T2 มั่นใจ | BN50: T3 เหตุผล | BO50: T4 มั่นใจ | BP50: T1 คำตอบ | BQ50: T2 มั่นใจ | BR50: T3 เหตุผล | BS50: T4 มั่นใจ | BT50: T1 คำตอบ | BU50: T2 มั่นใจ | BV50: T3 เหตุผล | BW50: T4 มั่นใจ | BX50: T1 คำตอบ | BY50: T2 มั่นใจ | BZ50: T3 เหตุผล | CA50: T4 มั่นใจ | CB50: T1 คำตอบ | CC50: T2 มั่นใจ | CD50: T3 เหตุผล | CE50: T4 มั่นใจ
B51: KEY | C51: ← กรอกเฉลยที่ถูกต้อง (T1 & T3) | D51: ข | E51: - | F51: 3 | G51: - | H51: ก | I51: - | J51: 4 | K51: - | L51: ค | M51: - | N51: 1 | O51: - | P51: ง | Q51: - | R51: 2 | S51: - | T51: ข | U51: - | V51: 4 | W51: - | X51: ค | Y51: - | Z51: 2 | AA51: - | AB51: ก | AC51: - | AD51: 3 | AE51: - | AF51: ง | AG51: - | AH51: 1 | AI51: - | AJ51: ข | AK51: - | AL51: 1 | AM51: - | AN51: ก | AO51: - | AP51: 3 | AQ51: - | AR51: ค | AS51: - | AT51: 4 | AU51: - | AV51: ง | AW51: - | AX51: 2 | AY51: - | AZ51: ข | BA51: - | BB51: 3 | BC51: - | BD51: ค | BE51: - | BF51: 1 | BG51: - | BH51: ก | BI51: - | BJ51: 4 | BK51: - | BL51: ง | BM51: - | BN51: 2 | BO51: - | BP51: ข | BQ51: - | BR51: 4 | BS51: - | BT51: ค | BU51: - | BV51: 2 | BW51: - | BX51: ก | BY51: - | BZ51: 3 | CA51: - | CB51: ง | CC51: - | CD51: 1 | CE51: -
B52: ='📥 ข้อมูลนักเรียน'!B4 | C52: ='📥 ข้อมูลนักเรียน'!C4
B53: ='📥 ข้อมูลนักเรียน'!B5 | C53: ='📥 ข้อมูลนักเรียน'!C5
B54: ='📥 ข้อมูลนักเรียน'!B6 | C54: ='📥 ข้อมูลนักเรียน'!C6
B55: ='📥 ข้อมูลนักเรียน'!B7 | C55: ='📥 ข้อมูลนักเรียน'!C7
B56: ='📥 ข้อมูลนักเรียน'!B8 | C56: ='📥 ข้อมูลนักเรียน'!C8
B57: ='📥 ข้อมูลนักเรียน'!B9 | C57: ='📥 ข้อมูลนักเรียน'!C9
B58: ='📥 ข้อมูลนักเรียน'!B10 | C58: ='📥 ข้อมูลนักเรียน'!C10
B59: ='📥 ข้อมูลนักเรียน'!B11 | C59: ='📥 ข้อมูลนักเรียน'!C11
B60: ='📥 ข้อมูลนักเรียน'!B12 | C60: ='📥 ข้อมูลนักเรียน'!C12
B61: ='📥 ข้อมูลนักเรียน'!B13 | C61: ='📥 ข้อมูลนักเรียน'!C13
B62: ='📥 ข้อมูลนักเรียน'!B14 | C62: ='📥 ข้อมูลนักเรียน'!C14
B63: ='📥 ข้อมูลนักเรียน'!B15 | C63: ='📥 ข้อมูลนักเรียน'!C15
... B91: ='📥 ข้อมูลนักเรียน'!B43 | C91: ='📥 ข้อมูลนักเรียน'!C43

Sheet 🤖 Four-tier วิเคราะห์
B1: 🤖 Auto-classify Four-tier Response Pattern (คำนวณอัตโนมัติ)
B3: 🔵 Pre-test — ผลการจำแนก (Auto)
B4: ที่ | C4: ชื่อนักเรียน | D4: ข้อ 1 | E4: ข้อ 2 | F4: ข้อ 3 | G4: ข้อ 4 | H4: ข้อ 5 | I4: ข้อ 6 | J4: ข้อ 7 | K4: ข้อ 8 | L4: ข้อ 9 | M4: ข้อ 10 | N4: ข้อ 11 | O4: ข้อ 12 | P4: ข้อ 13 | Q4: ข้อ 14 | R4: ข้อ 15 | S4: ข้อ 16 | T4: ข้อ 17 | U4: ข้อ 18 | V4: ข้อ 19 | W4: ข้อ 20 | X4: Sound ✅ | Y4: Misc. ❌ | Z4: Guess 🎲 | AA4: NoK ❓
